Traceback (most recent call last):
  File "C:\Users\rushpz\AppData\Local\Programs\Python\Python313\Lib\site-packages\jupyter_core\utils\__init__.py", line 154, in wrapped
    asyncio.get_running_loop()
    ~~~~~~~~~~~~~~~~~~~~~~~~^^
RuntimeError: no running event loop

During handling of the above exception, another exception occurred:

Traceback (most recent call last):
  File "C:\Users\rushpz\AppData\Local\Programs\Python\Python313\Lib\site-packages\jupyter_cache\executors\utils.py", line 58, in single_nb_execution
    executenb(
    ~~~~~~~~~^
        nb,
        ^^^
    ...<4 lines>...
        **kwargs,
        ^^^^^^^^^
    )
    ^
  File "C:\Users\rushpz\AppData\Local\Programs\Python\Python313\Lib\site-packages\nbclient\client.py", line 1319, in execute
    return NotebookClient(nb=nb, resources=resources, km=km, **kwargs).execute()
           ~~~~~~~~~~~~~~~~~~~~~~~~~~~~~~~~~~~~~~~~~~~~~~~~~~~~~~~~~~~~~~~~~~~^^
  File "C:\Users\rushpz\AppData\Local\Programs\Python\Python313\Lib\site-packages\jupyter_core\utils\__init__.py", line 158, in wrapped
    return loop.run_until_complete(inner)
           ~~~~~~~~~~~~~~~~~~~~~~~^^^^^^^
  File "C:\Users\rushpz\AppData\Local\Programs\Python\Python313\Lib\asyncio\base_events.py", line 725, in run_until_complete
    return future.result()
           ~~~~~~~~~~~~~^^
  File "C:\Users\rushpz\AppData\Local\Programs\Python\Python313\Lib\site-packages\nbclient\client.py", line 709, in async_execute
    await self.async_execute_cell(
        cell, index, execution_count=self.code_cells_executed + 1
    )
  File "C:\Users\rushpz\AppData\Local\Programs\Python\Python313\Lib\site-packages\nbclient\client.py", line 1062, in async_execute_cell
    await self._check_raise_for_error(cell, cell_index, exec_reply)
  File "C:\Users\rushpz\AppData\Local\Programs\Python\Python313\Lib\site-packages\nbclient\client.py", line 918, in _check_raise_for_error
    raise CellExecutionError.from_cell_and_msg(cell, exec_reply_content)
nbclient.exceptions.CellExecutionError: An error occurred while executing the following cell:
------------------
# Oh dear.
astronaut_mean_filtered = ndi.correlate(astronaut, 
                                        weights=mean_kernel)
------------------


[31m---------------------------------------------------------------------------[39m
[31mRuntimeError[39m                              Traceback (most recent call last)
[36mCell[39m[36m [39m[32mIn[34][39m[32m, line 2[39m
[32m      1[39m [38;5;66;03m# Oh dear.[39;00m
[32m----> [39m[32m2[39m astronaut_mean_filtered = [43mndi[49m[43m.[49m[43mcorrelate[49m[43m([49m[43mastronaut[49m[43m,[49m[43m [49m
[32m      3[39m [43m                                        [49m[43mweights[49m[43m=[49m[43mmean_kernel[49m[43m)[49m

[36mFile [39m[32m~\AppData\Local\Programs\Python\Python313\Lib\site-packages\scipy\ndimage\_filters.py:1373[39m, in [36mcorrelate[39m[34m(input, weights, output, mode, cval, origin, axes)[39m
[32m   1307[39m [38;5;129m@_ni_docstrings[39m.docfiller
[32m   1308[39m [38;5;28;01mdef[39;00m[38;5;250m [39m[34mcorrelate[39m([38;5;28minput[39m, weights, output=[38;5;28;01mNone[39;00m, mode=[33m'[39m[33mreflect[39m[33m'[39m, cval=[32m0.0[39m,
[32m   1309[39m               origin=[32m0[39m, *, axes=[38;5;28;01mNone[39;00m):
[32m   1310[39m [38;5;250m    [39m[33;03m"""[39;00m
[32m   1311[39m [33;03m    Multidimensional correlation.[39;00m
[32m   1312[39m 
[32m   (...)[39m[32m   1371[39m 
[32m   1372[39m [33;03m    """[39;00m
[32m-> [39m[32m1373[39m     [38;5;28;01mreturn[39;00m [43m_correlate_or_convolve[49m[43m([49m[38;5;28;43minput[39;49m[43m,[49m[43m [49m[43mweights[49m[43m,[49m[43m [49m[43moutput[49m[43m,[49m[43m [49m[43mmode[49m[43m,[49m[43m [49m[43mcval[49m[43m,[49m
[32m   1374[39m [43m                                  [49m[43morigin[49m[43m,[49m[43m [49m[38;5;28;43;01mFalse[39;49;00m[43m,[49m[43m [49m[43maxes[49m[43m)[49m

[36mFile [39m[32m~\AppData\Local\Programs\Python\Python313\Lib\site-packages\scipy\ndimage\_filters.py:1275[39m, in [36m_correlate_or_convolve[39m[34m(input, weights, output, mode, cval, origin, convolution, axes)[39m
[32m   1273[39m wshape = [ii [38;5;28;01mfor[39;00m ii [38;5;129;01min[39;00m weights.shape [38;5;28;01mif[39;00m ii > [32m0[39m]
[32m   1274[39m [38;5;28;01mif[39;00m [38;5;28mlen[39m(wshape) != [38;5;28minput[39m.ndim:
[32m-> [39m[32m1275[39m     [38;5;28;01mraise[39;00m [38;5;167;01mRuntimeError[39;00m([33mf[39m[33m"[39m[33mweights.ndim ([39m[38;5;132;01m{[39;00m[38;5;28mlen[39m(wshape)[38;5;132;01m}[39;00m[33m) must match [39m[33m"[39m
[32m   1276[39m                        [33mf[39m[33m"[39m[33mlen(axes) ([39m[38;5;132;01m{[39;00m[38;5;28mlen[39m(axes)[38;5;132;01m}[39;00m[33m)[39m[33m"[39m)
[32m   1277[39m [38;5;28;01mif[39;00m convolution:
[32m   1278[39m     weights = weights[[38;5;28mtuple[39m([[38;5;28mslice[39m([38;5;28;01mNone[39;00m, [38;5;28;01mNone[39;00m, -[32m1[39m)] * weights.ndim)]

[31mRuntimeError[39m: weights.ndim (2) must match len(axes) (3)

